Workbook

Sheet Analysis
A3: Row Labels | B3: Count of Place_ID
A4: Automotive Services | B4: 55
A5: B2B & Logistics | B5: 15
A6: Financial & Professional Services | B6: 41
A7: Health & Wellness | B7: 82
A8: Hospitality & Tourism | B8: 289
A9: Other | B9: 5
A10: Public & Community Services | B10: 79
A11: Retail & Shopping | B11: 127
A12: Grand Total | B12: 693

Sheet Dict
A1: Main_Classification | B1: Macro_Sector
A2: Restaurant | B2: Hospitality & Tourism
A3: Lodging | B3: Hospitality & Tourism
A4: Bar | B4: Hospitality & Tourism
A5: Cafe | B5: Hospitality & Tourism
A6: Night Club | B6: Hospitality & Tourism
A7: Casino | B7: Hospitality & Tourism
A8: Travel Agency | B8: Hospitality & Tourism
A9: Tourist Attraction | B9: Hospitality & Tourism
A10: Store | B10: Retail & Shopping
A11: Supermarket | B11: Retail & Shopping
A12: Grocery Or Supermarket | B12: Retail & Shopping
... A59: Food | B59: Retail & Shopping

Sheet Datos_from_API
A1: Place_ID | B1: Business_Name | C1: Target_Industry | D1: Main_Classification | E1: Macro_Sector | F1: Sub_Categories | G1: Price_Level_(0-4) | H1: Average_Rating | I1: Total_Reviews | J1: Address | K1: Latitude | L1: Longitude
A2: ChIJDfY6Avd_r44REWqUIsQAJQs | B2: Impuestos Internos | C2: Accounting | D2: Local Government Office | E2: =VLOOKUP(D2,Dict!A:B,2,FALSE) -> Public & Community Services | F2: Accounting, Finance, Point Of Interest, Establishment | G2: Not available | H2: 4.9 | I2: 8 | J2: Plaza Villa Florencia, Avenue 20 de Diciembre, local 102, Boca Chica | K2: 18.449174 | L2: -69.606467
A3: ChIJNwzJ-zh-r44RzNLvYgaJjPg | B3: MELC Solucines Agiles | C3: Accounting | D3: Accounting | E3: =VLOOKUP(D3,Dict!A:B,2,FALSE) -> Financial & Professional Services | F3: Finance, Point Of Interest, Establishment | G3: Not available | H3: 0 | I3: 0 | J3: Avenue Duarte 28, Boca Chica | K3: 18.447673 | L3: -69.606161
A4: ChIJtQyC_kZ-r44R6hx4hFhBgMQ | B4: Cajero Automatico Banco BHD | C4: Atm | D4: Atm | E4: =VLOOKUP(D4,Dict!A:B,2,FALSE) -> Financial & Professional Services | F4: Finance, Point Of Interest, Establishment | G4: Not available | H4: 3 | I4: 3 | J4: F93V+6GM, Boca Chica | K4: 18.453098 | L4: -69.60619
A5: ChIJG62zgzd-r44RBZ1MYpzssIk | B5: Bank Machine | C5: Atm | D5: Atm | E5: =VLOOKUP(D5,Dict!A:B,2,FALSE) -> Financial & Professional Services | F5: Finance, Point Of Interest, Establishment | G5: Not available | H5: 4.7 | I5: 3 | J5: C9XQ+5X9, Avenue Duarte, Boca Chica | K5: 18.447911 | L5: -69.61003
A6: ChIJS3AOhK5_r44Rv-hU7JC2oL8 | B6: ATM Cajero Triinet Whala! Boca Chica | C6: Atm | D6: Atm | E6: =VLOOKUP(D6,Dict!A:B,2,FALSE) -> Financial & Professional Services | F6: Finance, Point Of Interest, Establishment | G6: Not available | H6: 4.7 | I6: 3 | J6: C9WQ+RR Whala!, Boca Chica | K6: 18.447058 | L6: -69.610408
A7: ChIJCfNRFsx_r44RWyP09F-A3ug | B7: Cajero Automático Banco Popular | C7: Atm | D7: Atm | E7: =VLOOKUP(D7,Dict!A:B,2,FALSE) -> Financial & Professional Services | F7: Finance, Point Of Interest, Establishment | G7: Not available | H7: 5 | I7: 2 | J7: Calle San Andres 6, Andrés | K7: 18.445365 | L7: -69.626432
A8: ChIJS8-NI15_r44RZbxvvMU6vvU | B8: ATM Cajero Triinet Costa Linda | C8: Atm | D8: Atm | E8: =VLOOKUP(D8,Dict!A:B,2,FALSE) -> Financial & Professional Services | F8: Finance, Point Of Interest, Establishment | G8: Not available | H8: 3 | I8: 2 | J8: Hotel Costa Linda, Abraham Nunez 1, Boca Chica | K8: 18.447316 | L8: -69.608432
A9: ChIJ77Jec8F_r44R0FwRziQj-Cg | B9: Cajero automático Banco Popular | C9: Atm | D9: Atm | E9: =VLOOKUP(D9,Dict!A:B,2,FALSE) -> Financial & Professional Services | F9: Finance, Point Of Interest, Establishment | G9: Not available | H9: 5 | I9: 1 | J9: Avenue Duarte esq, Boca Chica | K9: 18.4479 | L9: -69.609842
A10: ChIJqbg4yyN_r44R7bLPPj8W3ic | B10: ATM Cajero Triinet Home Liquor | C10: Atm | D10: Atm | E10: =VLOOKUP(D10,Dict!A:B,2,FALSE) -> Financial & Professional Services | F10: Finance, Point Of Interest, Establishment | G10: Not available | H10: 4 | I10: 1 | J10: Home Liquor, Autopista Las Américas, Boca Chica | K10: 18.451082 | L10: -69.627901
A11: ChIJpa1HoWN_r44RP9tMWmELU4M | B11: ATM Cajero Triinet Boca Beach | C11: Atm | D11: Atm | E11: =VLOOKUP(D11,Dict!A:B,2,FALSE) -> Financial & Professional Services | F11: Finance, Point Of Interest, Establishment | G11: Not available | H11: 0 | I11: 0 | J11: Boca Beach Residence Hotel, Avenida Abraham Núñez, Boca Chica | K11: 18.447656 | L11: -69.613817
A12: ChIJq2dXVip_r44RvOgpAt0RzOM | B12: Cajero automático Banco Popular | C12: Atm | D12: Atm | E12: =VLOOKUP(D12,Dict!A:B,2,FALSE) -> Financial & Professional Services | F12: Finance, Point Of Interest, Establishment | G12: Not available | H12: 0 | I12: 0 | J12: Calle Andres Boca Chica No.16, Andres Boca Chica C/ Andres Boca Chica No.16, Boca Chica | K12: 18.445016 | L12: -69.627799
A13: ChIJ2Q1Dxbt_r44R4ytdQQmImv4 | B13: D'Jazmin Cake | C13: Bakery | D13: Bakery | E13: =VLOOKUP(D13,Dict!A:B,2,FALSE) -> Retail & Shopping | F13: Store, Point Of Interest, Food, Establishment | G13: Not available | H13: 4.3 | I13: 8 | J13: C9WF+VCJ, Calle Mella, Boca Chica | K13: 18.447203 | L13: -69.626474
... A24: ChIJ0yy1aTZ-r44RgNBlihJKMUU | B24: Banca solidaria boca chica | C24: Bank | D24: Bank | E24: =VLOOKUP(D24,Dict!A:B,2,FALSE) -> Financial & Professional Services | F24: Finance, Point Of Interest, Establishment | G24: Not available | H24: 0 | I24: 0 | J24: Avenue 20 de Diciembre 10, Boca Chica | K24: 18.449005 | L24: -69.614093
A25: ChIJLwbAbzd-r44RCIL21oErICM | B25: Mie by Sporting Club Boca Chica | C25: Bar | D25: Restaurant | E25: =VLOOKUP(D25,Dict!A:B,2,FALSE) -> Hospitality & Tourism | F25: Bar, Point Of Interest, Food, Establishment | G25: 2 | H25: 4.3 | I25: 1246 | J25: Avenida Abraham Núñez, Boca Chica | K25: 18.447381 | L25: -69.611148
A26: ChIJWXL8zzl-r44Rdhxy34frmtQ | B26: Mamajuana beach | C26: Bar | D26: Bar | E26: =VLOOKUP(D26,Dict!A:B,2,FALSE) -> Hospitality & Tourism | F26: Restaurant, Point Of Interest, Food, Establishment | G26: 2 | H26: 3 | I26: 166 | J26: Abraham Nunez 6, Boca Chica | K26: 18.446945 | L26: -69.608817
A27: ChIJ9Rhw8ct_r44RxD56E9dws70 | B27: FIRE DISCOTEC | C27: Bar | D27: Bar | E27: =VLOOKUP(D27,Dict!A:B,2,FALSE) -> Hospitality & Tourism | F27: Point Of Interest, Establishment | G27: 2 | H27: 4 | I27: 112 | J27: Calle Mella 4, Andrés | K27: 18.447189 | L27: -69.626487
A28: ChIJVa8DNTh-r44Rp7frHidP-PQ | B28: Tentacion Lounge Bar | C28: Bar | D28: Bar | E28: =VLOOKUP(D28,Dict!A:B,2,FALSE) -> Hospitality & Tourism | F28: Restaurant, Point Of Interest, Food, Establishment | G28: 2 | H28: 4.2 | I28: 77 | J28: ave. Duarte 25, Boca Chica, Boca Chica | K28: 18.447917 | L28: -69.608969
A29: ChIJ1aIDQyd_r44RFk4kBaYSOOs | B29: Piano Bar | C29: Bar | D29: Bar | E29: =VLOOKUP(D29,Dict!A:B,2,FALSE) -> Hospitality & Tourism | F29: Point Of Interest, Establishment | G29: 2 | H29: 3.9 | I29: 38 | J29: Avenue Duarte, Boca Chica | K29: 18.447867 | L29: -69.608746
A30: ChIJu8cpzNd_r44RvdKuudIezVs | B30: Amigos Night Life Boca Chica | C30: Bar | D30: Bar | E30: =VLOOKUP(D30,Dict!A:B,2,FALSE) -> Hospitality & Tourism | F30: Health, Point Of Interest, Establishment | G30: Not available | H30: 4 | I30: 34 | J30: Abraham Nunez 30, Boca Chica | K30: 18.447959 | L30: -69.612835
A31: ChIJlzS4nu9_r44RUBEIQu0QH1I | B31: Restaurante la oveja manza beach | C31: Bar | D31: Bar | E31: =VLOOKUP(D31,Dict!A:B,2,FALSE) -> Hospitality & Tourism | F31: Point Of Interest, Establishment | G31: Not available | H31: 4.5 | I31: 26 | J31: C9XM+4QM, Boca Chica | K31: 18.448125 | L31: -69.615371
A32: ChIJD7Y1tYt_r44RuP8GpMgQS6o | B32: Agiz Lounge • Restaurant | C32: Bar | D32: Bar | E32: =VLOOKUP(D32,Dict!A:B,2,FALSE) -> Hospitality & Tourism | F32: Point Of Interest, Establishment | G32: Not available | H32: 4 | I32: 24 | J32: C9WF+GP4, Andrés | K32: 18.446227 | L32: -69.625667
A33: ChIJ-SaFRXp_r44RdNG3X86qK8M | B33: Madre Lunch Bar | C33: Bar | D33: Bar | E33: =VLOOKUP(D33,Dict!A:B,2,FALSE) -> Hospitality & Tourism | F33: Point Of Interest, Establishment | G33: Not available | H33: 4.2 | I33: 21 | J33: Calle Mella 12, Andrés | K33: 18.447449 | L33: -69.626608
A34: ChIJvR-IKhSJr44Rtqjwm8OtwS4 | B34: Boca chicas | C34: Bar | D34: Bar | E34: =VLOOKUP(D34,Dict!A:B,2,FALSE) -> Hospitality & Tourism | F34: Point Of Interest, Establishment | G34: Not available | H34: 4.2 | I34: 17 | J34: F92R+6JM, Santo Domingo | K34: 18.450581 | L34: -69.608457
A35: ChIJz4u8k2N_r44R5SBVD2t3VPs | B35: LA EMBAJADA SOCIAL CLUB | C35: Bar | D35: Bar | E35: =VLOOKUP(D35,Dict!A:B,2,FALSE) -> Hospitality & Tourism | F35: Point Of Interest, Establishment | G35: Not available | H35: 4 | I35: 13 | J35: F98V+R85, Boca Chica | K35: 18.467 | L35: -69.606636
A36: ChIJjfLnjjt_r44RoEf0MvQhCDw | B36: La Cantina | C36: Bar | D36: Bar | E36: =VLOOKUP(D36,Dict!A:B,2,FALSE) -> Hospitality & Tourism | F36: Point Of Interest, Establishment | G36: Not available | H36: 4.8 | I36: 13 | J36: Calle San Andres 5, Andrés | K36: 18.447153 | L36: -69.626472
A37: ChIJyxeKmjh-r44R1ACbiOqLi68 | B37: Bodegas Max | C37: Bar | D37: Bar | E37: =VLOOKUP(D37,Dict!A:B,2,FALSE) -> Hospitality & Tourism | F37: Point Of Interest, Establishment | G37: Not available | H37: 4.1 | I37: 12 | J37: C9XV+RMC, Calle José Francisco Peña Goméz, Boca Chica | K37: 18.449574 | L37: -69.605861
A38: ChIJv3RBLTh-r44RMHcHJmKYZkk | B38: Dapathan | C38: Bar | D38: Bar | E38: =VLOOKUP(D38,Dict!A:B,2,FALSE) -> Hospitality & Tourism | F38: Point Of Interest, Establishment | G38: 2 | H38: 3.8 | I38: 12 | J38: Avenue Duarte 35, Boca Chica | K38: 18.44761 | L38: -69.608847
A39: ChIJa9KLTeB_r44RYRqn7dr7uSI | B39: Bryan Hookah Vape Store | C39: Bar | D39: Bar | E39: =VLOOKUP(D39,Dict!A:B,2,FALSE) -> Hospitality & Tourism | F39: Point Of Interest, Establishment | G39: Not available | H39: 3.6 | I39: 10 | J39: Prolongación caracol Calle Rafael Colon, Santo Domingo Este | K39: 18.459677 | L39: -69.605229
A40: ChIJS9hAQ9N_r44RnQj9G5vWa50 | B40: Billar Geymar | C40: Bar | D40: Bar | E40: =VLOOKUP(D40,Dict!A:B,2,FALSE) -> Hospitality & Tourism | F40: Point Of Interest, Establishment | G40: Not available | H40: 4 | I40: 10 | J40: F92P+GV, Juan Alberto Ozoria, Boca Chica | K40: 18.451348 | L40: -69.612893
A41: ChIJD_WXWMh_r44RSBeUIJfUCkQ | B41: Caffetteria da Michele | C41: Bar | D41: Bar | E41: =VLOOKUP(D41,Dict!A:B,2,FALSE) -> Hospitality & Tourism | F41: Point Of Interest, Establishment | G41: 1 | H41: 4.9 | I41: 8 | J41: Avenue Duarte 46, Boca Chica | K41: 18.447564 | L41: -69.607629
A42: ChIJZVNLUT9-r44R7O3rxN5HHiU | B42: Bejuko Bar | C42: Bar | D42: Bar | E42: =VLOOKUP(D42,Dict!A:B,2,FALSE) -> Hospitality & Tourism | F42: Point Of Interest, Establishment | G42: Not available | H42: 4.1 | I42: 7 | J42: C9XW+QP5, Calle Duarte, Boca Chica | K42: 18.449379 | L42: -69.603138
A43: ChIJh7kGkkR_r44RWOuUr0KxPJg | B43: Colmado disco bar | C43: Bar | D43: Bar | E43: =VLOOKUP(D43,Dict!A:B,2,FALSE) -> Hospitality & Tourism | F43: Point Of Interest, Establishment | G43: Not available | H43: 4.1 | I43: 7 | J43: F92V+7JM, Calle José Francisco Peña Goméz, Boca Chica | K43: 18.450713 | L43: -69.605966
A44: ChIJ6dK9yDh-r44RDjja1EVtTs0 | B44: Mr. Roger Bar | C44: Bar | D44: Bar | E44: =VLOOKUP(D44,Dict!A:B,2,FALSE) -> Hospitality & Tourism | F44: Point Of Interest, Establishment | G44: Not available | H44: 4.8 | I44: 5 | J44: Calle Duarte 26, Boca Chica | K44: 18.448229 | L44: -69.604252
A45: ChIJNzmrsZp_r44RjG_4rMjfAjw | B45: Pussycat Bar & Lounge | C45: Bar | D45: Bar | E45: =VLOOKUP(D45,Dict!A:B,2,FALSE) -> Hospitality & Tourism | F45: Point Of Interest, Establishment | G45: Not available | H45: 5 | I45: 5 | J45: Calle Duarte 21, Boca Chica | K45: 18.44932 | L45: -69.605312
A46: ChIJ-Tnx-eB_r44RuxqRRd43OT8 | B46: Puffy Drinks | C46: Bar | D46: Bar | E46: =VLOOKUP(D46,Dict!A:B,2,FALSE) -> Hospitality & Tourism | F46: Point Of Interest, Establishment | G46: Not available | H46: 5 | I46: 5 | J46: prolongacion caracol, Boca Chica | K46: 18.460566 | L46: -69.605365
A47: ChIJwYrGyGx_r44RFE3ds4Fcam0 | B47: Colmado music | C47: Bar | D47: Bar | E47: =VLOOKUP(D47,Dict!A:B,2,FALSE) -> Hospitality & Tourism | F47: Point Of Interest, Establishment | G47: Not available | H47: 4.5 | I47: 4 | J47: C9XR+4MC, Avenue Duarte, Boca Chica | K47: 18.4478 | L47: -69.608367
A48: ChIJCx5PI39_r44R0_ErzCAIQwk | B48: ISCAH ENTERPRISE INC | C48: Bar | D48: Car Wash | E48: =VLOOKUP(D48,Dict!A:B,2,FALSE) -> Automotive Services | F48: Beauty Salon, Bar, Point Of Interest, Establishment | G48: Not available | H48: 5 | I48: 4 | J48: Luis Leyba 39, Boca Chica | K48: 18.462381 | L48: -69.600579
A49: ChIJXW0ow0R_r44Rg5vcgB7jM9Q | B49: Manantial | C49: Bar | D49: Bar | E49: =VLOOKUP(D49,Dict!A:B,2,FALSE) -> Hospitality & Tourism | F49: Point Of Interest, Establishment | G49: Not available | H49: 3.5 | I49: 4 | J49: C9XJ+5G4, Calle Bahía San Andres, Boca Chica | K49: 18.447891 | L49: -69.618683
A50: ChIJ3wCmKgB_r44RoZHZyJuM_Bc | B50: YuYu Restaurant | C50: Bar | D50: Restaurant | E50: =VLOOKUP(D50,Dict!A:B,2,FALSE) -> Hospitality & Tourism | F50: Night Club, Bar, Point Of Interest, Food, Establishment | G50: Not available | H50: 5 | I50: 3 | J50: 18.447556,-69.607391, Avenue Duarte 24, Boca Chica | K50: 18.44763 | L50: -69.606988
...
